Workbook

Sheet Adquisiciones
A1: Categoría | B1: Equipo | C1: Referencia | D1: Cant. | E1: Precio Unitario (COP) | F1: Subtotal (COP) | G1: Link
A2: Robot | B2: Robot Paletizador | C2: ABB IRB 460-110/2.4 | D2: 1 | E2: 230000000 | F2: 230000000 | G2: https://new.abb.com/products/robotics/industrial-robots/irb-460
A3: Robot | B3: Controlador Robot | C3: ABB OmniCore C30 | D3: 1 | E3: Incluido | F3: Incluido | G3: https://new.abb.com/products/robotics/controllers/omnicore
A4: Robot | B4: FlexGripper Clamp | C4: ABB FlexGripper Clamp | D4: 1 | E4: 28000000 | F4: 28000000 | G4: https://library.e.abb.com/public/599e76150db34d35ac0c1e0b3708cc8e/FlexGripper+Family_Presentation_FT_JAN2018_EXTERNAL+DISTRIBUTION.pdf
A5: Seguridad | B5: Cortina de luz Tipo 4 | C5: REER EOS4 | D5: 3 | E5: 6500000 | F5: 19500000 | G5: https://www.reersafety.com/en/product/eos4-151-a-1310000/
A6: Seguridad | B6: Baliza LED | C6: PATLITE LR6 | D6: 2 | E6: 450000 | F6: 900000 | G6: https://www.patlite.com/product/detail0000000629.html
A7: Seguridad | B7: Panel Robo Fence | C7: Panel estándar | D7: 19 | E7: 1800000 | F7: 34200000 | G7: https://www.traceparts.com/els/squaregroup/en/search/robo-fencer-machine-guarding-panels-yellow-panels-with-black-mesh-25-mm-x-25-mm?CatalogPath=SQUARE_641530326%3ARFMG.020.010
A8: Seguridad | B8: Puerta Robo Fence | C8: Gate Assembly | D8: 1 | E8: 4500000 | F8: 4500000 | G8: https://www.traceparts.com/els/squaregroup/en/product/robo-fencer-machine-guarding-machine-guarding-1000-x-1800-mm-16-ga-solid-steel-slide-left-gate-assy?CatalogPath=SQUARE_641530326%3ARFMG.050.2.030&Product=90-13112024-035661&PartNumber=SGA.06.1000.1800.SL.1
A9: Operación | B9: Pedestal HMI | C9: Hoffmann | D9: 1 | E9: 2500000 | F9: 2500000 | G9: https://www.nvent.com/es-mx/hoffman/products/pedestal-system-0
A10: Logística | B10: Dispensador de pallets | C10: Quimarix | D10: 1 | E10: 42000000 | F10: 42000000 | G10: https://www.qimarox.es/producto/pallet-dispenser/
A11: Logística | B11: Estibas plásticas | C11: 1200×1000 mm | D11: 20 | E11: 280000 | F11: 5600000 | G11: https://www.orbiscorporation.com/es-mx/industries/industrial/plastic-pallets/
A12: Transporte | B12: Conveyor 950-4000 | C12: Interroll Modular | D12: 2 | E12: 28000000 | F12: 56000000 | G12: https://www.interroll.com/es/productos/mcp
A13: Transporte | B13: Conveyor 600 | C13: Interroll Modular | D13: 1 | E13: 18000000 | F13: 18000000 | G13: https://www.interroll.com/es/productos/mcp
A14: Eléctrico | B14: Gabinete IP66 | C14: Rittal VX25 | D14: 1 | E14: 8500000 | F14: 8500000 | G14: https://www.rittal.com/co-es/products/PG20231215SCH101/PG20240111SCH301/PRO83564
A15: Control | B15: PLC Principal | C15: Allen-Bradley ControlLogix 5580 | D15: 1 | E15: 75000000 | F15: 75000000 | G15: https://www.rockwellautomation.com/es-co/products/hardware/programmable-controllers/1756controllogix5580.html
... A24: Redes | B24: Patch Panel Industrial | C24: Cat6 Industrial | D24: 1 | E24: 1500000 | F24: 1500000 | G24: https://www.phoenixcontact.com/en-pc/products/industrial-communication/installation-technology-and-accessories/patch-panels
A25: Redes | B25: Cable Ethernet Industrial | C25: Cat6 Industrial | D25: 1 lote | E25: 8000000 | F25: 8000000 | G25: https://www.belden.com/products/cable/ethernet-cable/category-6-cable
A26: Redes | B26: Conectores M12 | C26: Ethernet/IP | D26: 30 | E26: 80000 | F26: 2400000 | G26: https://www.phoenixcontact.com/es-pc/cat/m12-ethernet-connectors-1592
A27: Software | B27: Siemens NX Design | C27: Licencia | D27: 1 | E27: 32000000 | F27: 32000000 | G27: https://plm.sw.siemens.com/nx
A28: Software | B28: Plant Simulation X Essentials | C28: Licencia | D28: 1 | E28: 22100000 | F28: 22100000 | G28: https://www.siemens.com/en-us/products/tecnomatix/offerings/plant-simulation-x-buyers-guide/?utm_source=chatgpt.com
A29: Software | B29: NX Mechatronics Concept Designer | C29: Licencia | D29: 1 | E29: 38000000 | F29: 38000000 | G29: https://plm.sw.siemens.com
A30: Software | B30: ABB Robot Studio | C30: Licencia | D30: 1 | E30: 17500000 | F30: 17500000 | G30: https://www.abb.com/global/en/areas/robotics/products/software/robotstudio-suite?TID=7205&utm_source=chatgpt.com
A31: Software | B31: Studio 5000 Logix Designer | C31: Professional | D31: 1 | E31: 22000000 | F31: 22000000 | G31: https://www.rockwellautomation.com
A32: Software | B32: FactoryTalk View Studio | C32: SE | D32: 1 | E32: 12000000 | F32: 12000000 | G32: https://www.rockwellautomation.com
A33: Software | B33: FactoryTalk Linx | C33: Runtime | D33: 1 | E33: 3500000 | F33: 3500000 | G33: https://www.rockwellautomation.com
E36: TOTAL | F36: =SUM(F2:F33) -> 751200000

Sheet EX+Beneficios
A1: OPEX | D1: FLUJO ELECTRICO
A2: Concepto | B2: Costo Estimado | D2: Variable | E2: Valor
A3: Mantenimiento Preventivo | B3: -5000000 | D3: Vatios x Hora de la maquinaria | E3: 9
A4: Repuestos y Consumibles | B4: -12000000
A5: Costo del Flujo Eléctrico | B5: =-1*E8 -> -32400000 | D5: Horas de uso | E5: 16
A6: Licencias Studio 5000 | B6: =-1*(Adquisiciones!E31+Adquisiciones!E32+Adquisiciones!E33) -> -37500000 | D6: Días de uso al año | E6: 300
A7: Licencias Plant Simulation | B7: =-1*(Adquisiciones!F28) -> -22100000 | D7: Costo del Flujo electrico kWh | E7: 750
A8: Licencias Robot Studio | B8: =-1*(Adquisiciones!F30) -> -17500000 | D8: TOTAL | E8: =E3*E5*E6*E7 -> 32400000
A9: Licencias SiemensNX | B9: =-1*(Adquisiciones!F29) -> -38000000
A10: Soporte Técnico | B10: -8000000
A11: TOTAL | B11: =SUM(B3:B10) -> -172500000
A13: CAPEX | D13: SALARIO DEL EQUIPO
A14: Concepto | B14: Costo Estimado | D14: Concepto | E14: Costo Estimado
A15: Adquisiciones | B15: =-1*Adquisiciones!F36-SUM(B6:B9) -> -636100000 | D15: Salario Base | E15: 5000000
A16: Instalación de Maquinaria (≈10%) | B16: =0.1*B15 -> -63610000 | D16: ARL | E16: 26100
A17: Capacitación del personal existente | B17: -15000000 | D17: Pensión | E17: 600000
A18: Documetación técnica y manuales | B18: -8000000 | D18: Salud | E18: 425000
A19: Puesta en Marcha y Pruebas | B19: 20000000
A20: Salario del equipo | B20: =-1*6*E21 -> -37506600 | D20: Caja de compensación | E20: 200000
A21: TOTAL | B21: =SUM(B15:B20) -> -740216600 | D21: TOTAL | E21: 6251100
A23: BENEFICIOS | D23: SALARIO DE OPERADORES | G23: PERDIDAS POR DAÑO ACCIDENTAL AL PALLET
A24: Concepto | B24: Costo Estimado | D24: Variable | E24: Cantidad | G24: Variable | H24: Cantidad
A25: Reducción Operadores de Paletizado | B25: =E28 -> 60767424 | D25: Salario Paletizador Anual | E25: 15191856 | G25: Peso Máximo Seguro Pallet | H25: 1500
A26: Ganancias x Aumento de Producción | B26: =Producción!J59 -> 1.0580049e+09 | D26: Número de Operadores x Turno | E26: 2 | G26: Precio por Litro de Bebida | H26: 2466
A27: Reducción perdidas por accidentes | B27: =H29 -> 2465740 | D27: Turnos | E27: 2 | G27: Incidentes de Caida de Pallet Anual | H27: 2
A28: TOTAL | B28: =SUM(B25:B27) -> 1.121238e+09 | D28: TOTAL | E28: 60767424 | G28: Porcentaje de bebida dañada por caída | H28: 0.33
G29: TOTAL | H29: 2465740

Sheet Producción
A1: INFORMACIÓN OBTENIDA POR VISITA | D1: LITRAJE
A2: Información | B2: Valor | D2: Bebidas | E2: Litros
A3: Tiempo alistamiento [horas] | B3: 1 | D3: Coca-Cola | E3: 2
A4: Tiempo saneamiento [minutos] | B4: 10 | D4: Quatro | E4: 1.75
A5: Rp | B5: 20000 | D5: Sprite | E5: 1.5
A6: Turnos | B6: 2
A7: Horas x Turno | B7: 8
A9: ESTUDIO DE MERCADO || COCA-COLA FEMSA | E9: Horas x Día
A10: Variable | B10: Valor | C10: Razón | E10: =B6*B7 -> 16
A11: Cajas consumidas | B11: 352300000 | C11: 1
A12: Bebidas Carbonatadas | B12: =B11*C12 -> 267748000 | C12: 0.76 | E12: % Pérdida Rp
A13: Presentación Familiar | B13: =B12*C13 -> 187423600 | C13: 0.7 | E13: 0.02
A14: Consumo Diario | B14: =ROUNDUP(B13*C14,0) -> 513490 | C14: =1/365 -> 0.002739726
A15: DESGLOSE POR VOLUMEN
A16: Cajas Diarias Coca-Cola | B16: =ROUNDUP(B14*C16,0) -> 256745 | C16: 0.5
A17: Cajas Diarias Quatro | B17: =ROUNDUP(B14*C17,0) -> 15405 | C17: 0.03
A18: Cajas Diarias Sprite | B18: =ROUNDUP(B14*C18,0) -> 15405 | C18: 0.03
A19: LITROS DIARIOS | E19: Cajas a oz
A20: Litros Diarios Coca-Cola | B20: =ROUNDUP(B16*$E$20*$E$22*C20,0) -> 728914 | C20: 0.5 | E20: =24*8 -> 192
A21: Litros Diarios Quatro | B21: =ROUNDUP(B17*$E$20*$E$22*C21,0) -> 43736 | C21: 0.5 | E21: oz a L
A22: Litros Diarios Sprite | B22: =ROUNDUP(B18*$E$20*$E$22*C22,0) -> 43736 | C22: 0.5 | E22: =29.5735/1000 -> 0.0295735
A23: UNIDADES DIARIAS
A24: Unidades Coca-Cola | B24: =ROUNDUP(B20/E3,0) -> 364457 | C24: 0.8706
A25: Unidades Quatro | B25: =ROUNDUP(B21/E4,0) -> 24992 | C25: 0.0597
A26: Unidades Sprite | B26: =ROUNDUP(B22/E5,0) -> 29158 | C26: 0.0697 | G26: ANEXO - RESULTADOS FINANCIEROS COCA-COLA 2024 | M26: Razón de Volúmen de Ventas
A27: Total Unidades - Nivel Nacional | B27: =SUM(B24:B26) -> 418607 | G27: Concepto | H27: USD | I27: COP | M27: Volúmen de Ventas | N27: 4225000000
G28: Volúmen de Ventas | H28: 4225000000 | I28: =H28 -> 4225000000 | M28: Volúmen de Ventas - Colombia | N28: 352300000
A29: UNIDADES DIARIAS - PLANTA Y PRECIO | G29: Ingresos Totales | H29: 13416000000 | I29: =H29*4409.15 -> 5.9153156e+13 | M29: Razón | N29: 0.0834
A30: Variable | B30: Unidades | C30: Valor | G30: Utilidad de Operación | H30: 1925000000 | I30: =H30*4409.15 -> 8.4876137e+12
A31: Unidades Coca-Cola | B31: =ROUND(B24*($D$50/$B$27),0) -> 182835 | C31: =B31*$N$35*E3 -> 9.0164715e+08 | G31: Utilidad Neta de la Participación Controladora | H31: 1138000000 | I31: =H31*4409.15 -> 5017612700000 | M31: Razón de Ingresos por Volumen
A32: Unidades Quatro | B32: =ROUND(B25*($D$50/$B$27),0) -> 12538 | C32: =B32*$N$35*E4 -> 54102034 | G32: Activos Totales | H32: 14767000000 | I32: =H32*4409.15 -> 6.5109918e+13 | M32: Volúmen de Ventas | N32: 4225000000
A33: Unidades Sprite | B33: =ROUND(B26*($D$50/$B$27),0) -> 14628 | C33: =B33*$N$35*E5 -> 54103267 | G33: Deuda a Largo Plazo y Documentos por Pagar | H33: 3375000000 | I33: =H33*4409.15 -> 1.4880881e+13 | M33: Ingresos Totales | N33: 59153156400000
A34: UNIDADES DIARIAS - UTILIDAD | G34: Participación Controladora | H34: 6877000000 | I34: =H34*4409.15 -> 3.0321725e+13 | M34: Precio de Venta x Caja | N34: 14000.75
A35: Variable | B35: Valor | C35: Razón | G35: Inversión en Activo Fijo | H35: 1410000000 | I35: =H36*4409.15 -> 308.6405 | M35: Precio de Venta x Litro | N35: 2465.74
A36: Utilidad Coca-Cola | B36: =C31*C36 -> 1.2938637e+08 | C36: =$N$40 -> 0.1435 | G36: Utilidad por Acción | H36: 0.07 | I36: 0.07
A37: Utilidad Quatro | B37: =C32*C37 -> 7763641.9 | C37: =$N$40 -> 0.1435 | M37: Razón de Utilidad
A38: Utilidad Sprite | B38: =C33*C38 -> 7763818.8 | C38: =$N$40 -> 0.1435 | M38: Ingresos Totales | N38: 59153156400000
A39: Utilidad - Nivel Nacional | B39: =SUM(B36:B38) -> 1.4491383e+08 | M39: Utilidad de Operación | N39: 8487613750000
A40: Utilidad Anual | B40: =B39*365.25 -> 5.2929775e+10 | M40: Razón | N40: 0.1435
A42: TAKT TIME | D42: Tiempo Planeación de ejecución | G42: CALCULADORA - AUMENTO DE PRODUCTIVIDAD
...

Sheet Flujo de Caja
A1: AÑO | B1: OPEX + CAPEX | C1: INGREOS | D1: FLUJO NETO | E1: FLUJO ACUMULADO | F1: VPN | G1: ROI | I1: Indicadores:
A2: 1 | B2: ='EX+Beneficios'!B11+'EX+Beneficios'!B21 -> -912716600 | C2: 0 | D2: =C2+B2 -> -912716600 | E2: =D2 -> -912716600 | F2: =NPV($J$2,D2) -> -8.2786086e+08 | G2: =F2/-$D$2 -> -0.90702948 | I2: Tasa de Mercado | J2: 0.1025
A3: 2 | B3: =B2 -> -912716600 | C3: ='EX+Beneficios'!B28 -> 1.121238e+09 | D3: =C3+B3 -> 2.0852145e+08 | E3: =E2+D3 -> -7.0419515e+08 | F3: =NPV($J$2,$D$2:D3) -> -6.5630975e+08 | G3: =F3/-$D$2 -> -0.71907288 | I3: Payback | J3: =A21+(-E21/D21) -> 5.3770874
A4: 3 | B4: =B3 -> -912716600 | C4: =C3 -> 1.121238e+09 | D4: =C4+B4 -> 2.0852145e+08 | E4: =E3+D4 -> -4.956737e+08 | F4: =NPV($J$2,$D$2:D4) -> -5.0070784e+08 | G4: =F4/-$D$2 -> -0.5485907 | I4: TIR | J4: =IRR(D2:D21) -> 0.22351674
A5: 4 | B5: =B4 -> -912716600 | C5: =C4 -> 1.121238e+09 | D5: =C5+B5 -> 2.0852145e+08 | E5: =E4+D5 -> -2.8715226e+08 | F5: =NPV($J$2,$D$2:D5) -> -3.5957231e+08 | G5: =F5/-$D$2 -> -0.39395834
A6: 5 | B6: =B5 -> -912716600 | C6: =C5 -> 1.121238e+09 | D6: =C6+B6 -> 2.0852145e+08 | E6: =E5+D6 -> -78630810 | F6: =NPV($J$2,$D$2:D6) -> -2.3155823e+08 | G6: =F6/-$D$2 -> -0.25370223
A7: 6 | B7: =B6 -> -912716600 | C7: =C6 -> 1.121238e+09 | D7: =C7+B7 -> 2.0852145e+08 | E7: =E6+D7 -> 1.2989064e+08 | F7: =NPV($J$2,$D$2:D7) -> -1.1544569e+08 | G7: =F7/-$D$2 -> -0.1264858
A8: 7 | B8: =B7 -> -912716600 | C8: =C7 -> 1.121238e+09 | D8: =C8+B8 -> 2.0852145e+08 | E8: =E7+D8 -> 3.3841209e+08 | F8: =NPV($J$2,$D$2:D8) -> -10128187 | G8: =F8/-$D$2 -> -0.011096749
A9: 8 | B9: =B8 -> -912716600 | C9: =C8 -> 1.121238e+09 | D9: =C9+B9 -> 2.0852145e+08 | E9: =E8+D9 -> 5.4693353e+08 | F9: =NPV($J$2,$D$2:D9) -> 85397891 | G9: =F9/-$D$2 -> 0.09356452
A10: 9 | B10: =B9 -> -912716600 | C10: =C9 -> 1.121238e+09 | D10: =C10+B10 -> 2.0852145e+08 | E10: =E9+D10 -> 7.5545498e+08 | F10: =NPV($J$2,$D$2:D10) -> 1.7204286e+08 | G10: =F10/-$D$2 -> 0.18849538
A11: 10 | B11: =B10 -> -912716600 | C11: =C10 -> 1.121238e+09 | D11: =C11+B11 -> 2.0852145e+08 | E11: =E10+D11 -> 9.6397643e+08 | F11: =NPV($J$2,$D$2:D11) -> 2.506324e+08 | G11: =F11/-$D$2 -> 0.27460046
A12: 11 | B12: =B11 -> -912716600 | C12: =C11 -> 1.121238e+09 | D12: =C12+B12 -> 2.0852145e+08 | E12: =E11+D12 -> 1.1724979e+09 | F12: =NPV($J$2,$D$2:D12) -> 3.2191543e+08 | G12: =F12/-$D$2 -> 0.35270031
A13: 12 | B13: =B12 -> -912716600 | C13: =C12 -> 1.121238e+09 | D13: =C13+B13 -> 2.0852145e+08 | E13: =E12+D13 -> 1.3810193e+09 | F13: =NPV($J$2,$D$2:D13) -> 3.8657124e+08 | G13: =F13/-$D$2 -> 0.42353918
A14: 13 | B14: =B13 -> -912716600 | C14: =C13 -> 1.121238e+09 | D14: =C14+B14 -> 2.0852145e+08 | E14: =E13+D14 -> 1.5895408e+09 | F14: =NPV($J$2,$D$2:D14) -> 4.4521596e+08 | G14: =F14/-$D$2 -> 0.48779212
A15: 14 | B15: =B14 -> -912716600 | C15: =C14 -> 1.121238e+09 | D15: =C15+B15 -> 2.0852145e+08 | E15: =E14+D15 -> 1.7980622e+09 | F15: =NPV($J$2,$D$2:D15) -> 4.9840846e+08 | G15: =F15/-$D$2 -> 0.54607143
A16: 15 | B16: =B15 -> -912716600 | C16: =C15 -> 1.121238e+09 | D16: =C16+B16 -> 2.0852145e+08 | E16: =E15+D16 -> 2.0065837e+09 | F16: =NPV($J$2,$D$2:D16) -> 5.4665562e+08 | G16: =F16/-$D$2 -> 0.59893248
... A21: 20 | B21: =B20 -> -912716600 | C21: =C20 -> 1.121238e+09 | D21: =C21+B21 -> 2.0852145e+08 | E21: =E20+D21 -> 3.0491909e+09 | F21: =NPV($J$2,$D$2:D21) -> 7.283882e+08 | G21: =F21/-$D$2 -> 0.79804421

Sheet Curva S
A1: MES | B1: CONCEPTO | C1: % DEL PRESUPUESTO | D1: COSTO X MES | E1: COSTO ACUMULADO
A2: 0 | B2: - | C2: 0 | D2: 0 | E2: =D2 -> 0
A3: 1 | B3: Planeación | C3: 0.01 | D3: =-C3*'EX+Beneficios'!$B$21 -> 7402166 | E3: =D3 -> 7402166
A4: 2 | B4: Ingenieria y Diseño | C4: 0.15 | D4: =-C4*'EX+Beneficios'!$B$21 -> 111032490 | E4: =E3+D4 -> 118434656
A5: 3 | B5: compra de equipos | C5: 0.5 | D5: =-C5*'EX+Beneficios'!$B$21 -> 370108300 | E5: =E4+D5 -> 488542956
A6: 4 | B6: Instalación eléctrica | C6: 0.1 | D6: =-C6*'EX+Beneficios'!$B$21 -> 74021660 | E6: =E5+D6 -> 562564616
A7: 5 | B7: Programación equipos | C7: 0.08 | D7: =-C7*'EX+Beneficios'!$B$21 -> 59217328 | E7: =E6+D7 -> 621781944
A8: 6 | B8: Integración del robot | C8: 0.1 | D8: =-C8*'EX+Beneficios'!$B$21 -> 74021660 | E8: =E7+D8 -> 695803604
A9: 7 | B9: Pruebas y puesta en marcha | C9: 0.04 | D9: =-C9*'EX+Beneficios'!$B$21 -> 29608664 | E9: =E8+D9 -> 725412268
A10: 8 | B10: Capacitación y documentación | C10: 0.02 | D10: =-C10*'EX+Beneficios'!$B$21 -> 14804332 | E10: =E9+D10 -> 740216600
